2024-10-22 18:39:28,874 ERROR: Exception on /graphicks/0 [GET] [in C:\Users\Sergey\AppData\Local\Programs\Python\Python311\Lib\site-packages\flask\app.py:838]
Traceback (most recent call last):
  File "C:\Users\Sergey\AppData\Local\Programs\Python\Python311\Lib\site-packages\flask\app.py", line 1473, in wsgi_app
    response = self.full_dispatch_request()
               ^^^^^^^^^^^^^^^^^^^^^^^^^^^^
  File "C:\Users\Sergey\AppData\Local\Programs\Python\Python311\Lib\site-packages\flask\app.py", line 882, in full_dispatch_request
    rv = self.handle_user_exception(e)
         ^^^^^^^^^^^^^^^^^^^^^^^^^^^^^
  File "C:\Users\Sergey\AppData\Local\Programs\Python\Python311\Lib\site-packages\flask\app.py", line 880, in full_dispatch_request
    rv = self.dispatch_request()
         ^^^^^^^^^^^^^^^^^^^^^^^
  File "C:\Users\Sergey\AppData\Local\Programs\Python\Python311\Lib\site-packages\flask\app.py", line 865, in dispatch_request
    return self.ensure_sync(self.view_functions[rule.endpoint])(**view_args)  # type: ignore[no-any-return]
           ^^^^^^^^^^^^^^^^^^^^^^^^^^^^^^^^^^^^^^^^^^^^^^^^^^^^^^^^^^^^^^^^^
  File "C:\Users\Sergey\Desktop\Brainfor\app\main\routes.py", line 328, in graphic
    temp.append({hour: les.datatimes.hour, minute: les.datatimes.minute})
                 ^^^^
NameError: name 'hour' is not defined
2024-10-22 18:39:53,391 INFO: Microblog startup [in C:\Users\Sergey\Desktop\Brainfor\app\__init__.py:57]
2024-10-22 18:39:55,109 ERROR: Exception on /graphicks/0 [GET] [in C:\Users\Sergey\AppData\Local\Programs\Python\Python311\Lib\site-packages\flask\app.py:838]
Traceback (most recent call last):
  File "C:\Users\Sergey\AppData\Local\Programs\Python\Python311\Lib\site-packages\flask\app.py", line 1473, in wsgi_app
    response = self.full_dispatch_request()
               ^^^^^^^^^^^^^^^^^^^^^^^^^^^^
  File "C:\Users\Sergey\AppData\Local\Programs\Python\Python311\Lib\site-packages\flask\app.py", line 882, in full_dispatch_request
    rv = self.handle_user_exception(e)
         ^^^^^^^^^^^^^^^^^^^^^^^^^^^^^
  File "C:\Users\Sergey\AppData\Local\Programs\Python\Python311\Lib\site-packages\flask\app.py", line 880, in full_dispatch_request
    rv = self.dispatch_request()
         ^^^^^^^^^^^^^^^^^^^^^^^
  File "C:\Users\Sergey\AppData\Local\Programs\Python\Python311\Lib\site-packages\flask\app.py", line 865, in dispatch_request
    return self.ensure_sync(self.view_functions[rule.endpoint])(**view_args)  # type: ignore[no-any-return]
           ^^^^^^^^^^^^^^^^^^^^^^^^^^^^^^^^^^^^^^^^^^^^^^^^^^^^^^^^^^^^^^^^^
  File "C:\Users\Sergey\Desktop\Brainfor\app\main\routes.py", line 328, in graphic
    temp.append({'hour': les.datatimes.hour, 'minute': les.datatimes.minute})
                         ^^^^^^^^^^^^^
AttributeError: 'Lesson' object has no attribute 'datatimes'
2024-10-22 18:40:32,236 INFO: Microblog startup [in C:\Users\Sergey\Desktop\Brainfor\app\__init__.py:57]
2024-10-22 21:07:11,673 INFO: Microblog startup [in C:\Users\Sergey\Desktop\Brainfor\app\__init__.py:57]
2024-10-22 21:07:15,013 ERROR: Exception on /profile/ [GET] [in C:\Users\Sergey\AppData\Local\Programs\Python\Python311\Lib\site-packages\flask\app.py:838]
Traceback (most recent call last):
  File "C:\Users\Sergey\AppData\Local\Programs\Python\Python311\Lib\site-packages\flask\app.py", line 1473, in wsgi_app
    response = self.full_dispatch_request()
               ^^^^^^^^^^^^^^^^^^^^^^^^^^^^
  File "C:\Users\Sergey\AppData\Local\Programs\Python\Python311\Lib\site-packages\flask\app.py", line 882, in full_dispatch_request
    rv = self.handle_user_exception(e)
         ^^^^^^^^^^^^^^^^^^^^^^^^^^^^^
  File "C:\Users\Sergey\AppData\Local\Programs\Python\Python311\Lib\site-packages\flask\app.py", line 880, in full_dispatch_request
    rv = self.dispatch_request()
         ^^^^^^^^^^^^^^^^^^^^^^^
  File "C:\Users\Sergey\AppData\Local\Programs\Python\Python311\Lib\site-packages\flask\app.py", line 865, in dispatch_request
    return self.ensure_sync(self.view_functions[rule.endpoint])(**view_args)  # type: ignore[no-any-return]
           ^^^^^^^^^^^^^^^^^^^^^^^^^^^^^^^^^^^^^^^^^^^^^^^^^^^^^^^^^^^^^^^^^
  File "C:\Users\Sergey\AppData\Local\Programs\Python\Python311\Lib\site-packages\flask_login\utils.py", line 290, in decorated_view
    return current_app.ensure_sync(func)(*args, **kwargs)
           ^^^^^^^^^^^^^^^^^^^^^^^^^^^^^^^^^^^^^^^^^^^^^^
  File "C:\Users\Sergey\Desktop\Brainfor\app\main\routes.py", line 36, in information
    if not info.id_user:
           ^^^^^^^^^^^^
AttributeError: 'NoneType' object has no attribute 'id_user'
2024-10-22 21:07:52,622 INFO: Microblog startup [in C:\Users\Sergey\Desktop\Brainfor\app\__init__.py:57]
2024-10-22 21:07:57,445 ERROR: Exception on /profile/ [GET] [in C:\Users\Sergey\AppData\Local\Programs\Python\Python311\Lib\site-packages\flask\app.py:838]
Traceback (most recent call last):
  File "C:\Users\Sergey\AppData\Local\Programs\Python\Python311\Lib\site-packages\flask\app.py", line 1473, in wsgi_app
    response = self.full_dispatch_request()
               ^^^^^^^^^^^^^^^^^^^^^^^^^^^^
  File "C:\Users\Sergey\AppData\Local\Programs\Python\Python311\Lib\site-packages\flask\app.py", line 882, in full_dispatch_request
    rv = self.handle_user_exception(e)
         ^^^^^^^^^^^^^^^^^^^^^^^^^^^^^
  File "C:\Users\Sergey\AppData\Local\Programs\Python\Python311\Lib\site-packages\flask\app.py", line 880, in full_dispatch_request
    rv = self.dispatch_request()
         ^^^^^^^^^^^^^^^^^^^^^^^
  File "C:\Users\Sergey\AppData\Local\Programs\Python\Python311\Lib\site-packages\flask\app.py", line 865, in dispatch_request
    return self.ensure_sync(self.view_functions[rule.endpoint])(**view_args)  # type: ignore[no-any-return]
           ^^^^^^^^^^^^^^^^^^^^^^^^^^^^^^^^^^^^^^^^^^^^^^^^^^^^^^^^^^^^^^^^^
  File "C:\Users\Sergey\AppData\Local\Programs\Python\Python311\Lib\site-packages\flask_login\utils.py", line 290, in decorated_view
    return current_app.ensure_sync(func)(*args, **kwargs)
           ^^^^^^^^^^^^^^^^^^^^^^^^^^^^^^^^^^^^^^^^^^^^^^
  File "C:\Users\Sergey\Desktop\Brainfor\app\main\routes.py", line 36, in information
    if not info.id_user:
           ^^^^^^^^^^^^
AttributeError: 'NoneType' object has no attribute 'id_user'
2024-10-22 21:08:46,136 INFO: Microblog startup [in C:\Users\Sergey\Desktop\Brainfor\app\__init__.py:57]
2024-10-22 22:12:59,675 INFO: Microblog startup [in C:\Users\Sergey\Desktop\Brainfor\app\__init__.py:57]
2024-10-23 00:42:04,939 ERROR: Exception on /sudo_graph [GET] [in C:\Users\Sergey\AppData\Local\Programs\Python\Python311\Lib\site-packages\flask\app.py:838]
Traceback (most recent call last):
  File "C:\Users\Sergey\AppData\Local\Programs\Python\Python311\Lib\site-packages\flask\app.py", line 1473, in wsgi_app
    response = self.full_dispatch_request()
               ^^^^^^^^^^^^^^^^^^^^^^^^^^^^
  File "C:\Users\Sergey\AppData\Local\Programs\Python\Python311\Lib\site-packages\flask\app.py", line 882, in full_dispatch_request
    rv = self.handle_user_exception(e)
         ^^^^^^^^^^^^^^^^^^^^^^^^^^^^^
  File "C:\Users\Sergey\AppData\Local\Programs\Python\Python311\Lib\site-packages\flask\app.py", line 880, in full_dispatch_request
    rv = self.dispatch_request()
         ^^^^^^^^^^^^^^^^^^^^^^^
  File "C:\Users\Sergey\AppData\Local\Programs\Python\Python311\Lib\site-packages\flask\app.py", line 865, in dispatch_request
    return self.ensure_sync(self.view_functions[rule.endpoint])(**view_args)  # type: ignore[no-any-return]
           ^^^^^^^^^^^^^^^^^^^^^^^^^^^^^^^^^^^^^^^^^^^^^^^^^^^^^^^^^^^^^^^^^
  File "C:\Users\Sergey\AppData\Local\Programs\Python\Python311\Lib\site-packages\flask_login\utils.py", line 290, in decorated_view
    return current_app.ensure_sync(func)(*args, **kwargs)
           ^^^^^^^^^^^^^^^^^^^^^^^^^^^^^^^^^^^^^^^^^^^^^^
  File "C:\Users\Sergey\Desktop\Brainfor\app\main\admin_panel\admin_routes.py", line 206, in sudo_graph
    return render_template('admin_panel/sudo_graph.html', graph=graph, rolee=role, lenss=lenss, to_total=to_total, less=less)
           ^^^^^^^^^^^^^^^^^^^^^^^^^^^^^^^^^^^^^^^^^^^^^^^^^^^^^^^^^^^^^^^^^^^^^^^^^^^^^^^^^^^^^^^^^^^^^^^^^^^^^^^^^^^^^^^^^^
  File "C:\Users\Sergey\AppData\Local\Programs\Python\Python311\Lib\site-packages\flask\templating.py", line 150, in render_template
    return _render(app, template, context)
           ^^^^^^^^^^^^^^^^^^^^^^^^^^^^^^^
  File "C:\Users\Sergey\AppData\Local\Programs\Python\Python311\Lib\site-packages\flask\templating.py", line 131, in _render
    rv = template.render(context)
         ^^^^^^^^^^^^^^^^^^^^^^^^
  File "C:\Users\Sergey\AppData\Local\Programs\Python\Python311\Lib\site-packages\jinja2\environment.py", line 1304, in render
    self.environment.handle_exception()
  File "C:\Users\Sergey\AppData\Local\Programs\Python\Python311\Lib\site-packages\jinja2\environment.py", line 939, in handle_exception
    raise rewrite_traceback_stack(source=source)
  File "C:\Users\Sergey\Desktop\Brainfor\app\templates\admin_panel\sudo_graph.html", line 1, in top-level template code
    {% extends 'base.html' %}
  File "C:\Users\Sergey\Desktop\Brainfor\app\templates\base.html", line 52, in top-level template code
    {% block app_content %}
  File "C:\Users\Sergey\Desktop\Brainfor\app\templates\admin_panel\sudo_graph.html", line 12, in block 'app_content'
    <li style="background-color: lightgreen">Total pass lessons {{ tot_pass[i] }}</li>
    ^^^^^^^^^^^^^^^^^^^^^^^^^
  File "C:\Users\Sergey\AppData\Local\Programs\Python\Python311\Lib\site-packages\jinja2\environment.py", line 468, in getitem
    return obj[argument]
           ~~~^^^^^^^^^^
jinja2.exceptions.UndefinedError: 'tot_pass' is undefined
2024-10-23 12:45:36,466 INFO: Microblog startup [in C:\Users\Sergey\Desktop\Brainfor\app\__init__.py:57]
2024-10-23 12:46:22,155 INFO: Microblog startup [in C:\Users\Sergey\Desktop\Brainfor\app\__init__.py:57]
2024-10-23 12:51:07,520 INFO: Microblog startup [in C:\Users\Sergey\Desktop\Brainfor\app\__init__.py:57]
