2024-10-28 01:58:49,158 ERROR: Exception on /sudo_graph [GET] [in C:\Users\Sergey\AppData\Local\Programs\Python\Python311\Lib\site-packages\flask\app.py:838]
Traceback (most recent call last):
  File "C:\Users\Sergey\AppData\Local\Programs\Python\Python311\Lib\site-packages\flask\app.py", line 1473, in wsgi_app
    response = self.full_dispatch_request()
               ^^^^^^^^^^^^^^^^^^^^^^^^^^^^
  File "C:\Users\Sergey\AppData\Local\Programs\Python\Python311\Lib\site-packages\flask\app.py", line 882, in full_dispatch_request
    rv = self.handle_user_exception(e)
         ^^^^^^^^^^^^^^^^^^^^^^^^^^^^^
  File "C:\Users\Sergey\AppData\Local\Programs\Python\Python311\Lib\site-packages\flask\app.py", line 880, in full_dispatch_request
    rv = self.dispatch_request()
         ^^^^^^^^^^^^^^^^^^^^^^^
  File "C:\Users\Sergey\AppData\Local\Programs\Python\Python311\Lib\site-packages\flask\app.py", line 865, in dispatch_request
    return self.ensure_sync(self.view_functions[rule.endpoint])(**view_args)  # type: ignore[no-any-return]
           ^^^^^^^^^^^^^^^^^^^^^^^^^^^^^^^^^^^^^^^^^^^^^^^^^^^^^^^^^^^^^^^^^
  File "C:\Users\Sergey\AppData\Local\Programs\Python\Python311\Lib\site-packages\flask_login\utils.py", line 290, in decorated_view
    return current_app.ensure_sync(func)(*args, **kwargs)
           ^^^^^^^^^^^^^^^^^^^^^^^^^^^^^^^^^^^^^^^^^^^^^^
  File "C:\Users\Sergey\Desktop\Brainfor\app\main\admin_panel\admin_routes.py", line 208, in sudo_graph
    return render_template('admin_panel/sudo_graph.html', graph=graph, rolee=role, lenss=lenss, to_total=to_total, less=less)
           ^^^^^^^^^^^^^^^^^^^^^^^^^^^^^^^^^^^^^^^^^^^^^^^^^^^^^^^^^^^^^^^^^^^^^^^^^^^^^^^^^^^^^^^^^^^^^^^^^^^^^^^^^^^^^^^^^^
  File "C:\Users\Sergey\AppData\Local\Programs\Python\Python311\Lib\site-packages\flask\templating.py", line 150, in render_template
    return _render(app, template, context)
           ^^^^^^^^^^^^^^^^^^^^^^^^^^^^^^^
  File "C:\Users\Sergey\AppData\Local\Programs\Python\Python311\Lib\site-packages\flask\templating.py", line 131, in _render
    rv = template.render(context)
         ^^^^^^^^^^^^^^^^^^^^^^^^
  File "C:\Users\Sergey\AppData\Local\Programs\Python\Python311\Lib\site-packages\jinja2\environment.py", line 1304, in render
    self.environment.handle_exception()
  File "C:\Users\Sergey\AppData\Local\Programs\Python\Python311\Lib\site-packages\jinja2\environment.py", line 939, in handle_exception
    raise rewrite_traceback_stack(source=source)
  File "C:\Users\Sergey\Desktop\Brainfor\app\templates\admin_panel\sudo_graph.html", line 1, in top-level template code
    {% extends 'base.html' %}
  File "C:\Users\Sergey\Desktop\Brainfor\app\templates\base.html", line 52, in top-level template code
    {% block app_content %}
  File "C:\Users\Sergey\Desktop\Brainfor\app\templates\admin_panel\sudo_graph.html", line 12, in block 'app_content'
    <li style="background-color: lightgreen">Total pass lessons {{ tot_pass[i] }}</li>
    ^^^^^^^^^^^^^^^^^^^^^^^^^
  File "C:\Users\Sergey\AppData\Local\Programs\Python\Python311\Lib\site-packages\jinja2\environment.py", line 468, in getitem
    return obj[argument]
           ~~~^^^^^^^^^^
jinja2.exceptions.UndefinedError: 'tot_pass' is undefined
2024-10-28 02:01:34,809 INFO: Microblog startup [in C:\Users\Sergey\Desktop\Brainfor\app\__init__.py:57]
2024-10-28 02:04:38,422 INFO: Microblog startup [in C:\Users\Sergey\Desktop\Brainfor\app\__init__.py:57]
2024-10-28 02:05:02,691 INFO: Microblog startup [in C:\Users\Sergey\Desktop\Brainfor\app\__init__.py:57]
