2024-10-23 13:39:27,567 ERROR: Exception on /create_lesson/15 [GET] [in C:\Users\Sergey\AppData\Local\Programs\Python\Python311\Lib\site-packages\flask\app.py:838]
Traceback (most recent call last):
  File "C:\Users\Sergey\AppData\Local\Programs\Python\Python311\Lib\site-packages\flask\app.py", line 1473, in wsgi_app
    response = self.full_dispatch_request()
               ^^^^^^^^^^^^^^^^^^^^^^^^^^^^
  File "C:\Users\Sergey\AppData\Local\Programs\Python\Python311\Lib\site-packages\flask\app.py", line 882, in full_dispatch_request
    rv = self.handle_user_exception(e)
         ^^^^^^^^^^^^^^^^^^^^^^^^^^^^^
  File "C:\Users\Sergey\AppData\Local\Programs\Python\Python311\Lib\site-packages\flask\app.py", line 880, in full_dispatch_request
    rv = self.dispatch_request()
         ^^^^^^^^^^^^^^^^^^^^^^^
  File "C:\Users\Sergey\AppData\Local\Programs\Python\Python311\Lib\site-packages\flask\app.py", line 865, in dispatch_request
    return self.ensure_sync(self.view_functions[rule.endpoint])(**view_args)  # type: ignore[no-any-return]
           ^^^^^^^^^^^^^^^^^^^^^^^^^^^^^^^^^^^^^^^^^^^^^^^^^^^^^^^^^^^^^^^^^
  File "C:\Users\Sergey\Desktop\Brainfor\app\main\teacher_panel\teacher_routes.py", line 210, in create_lesson_get
    party = db.session.query(Part_Course).filter(Part_Course.id_course == course.id).order_by(Part_Course.number).all()
                                                                          ^^^^^^^^^
AttributeError: 'NoneType' object has no attribute 'id'
2024-10-23 13:47:07,105 INFO: Microblog startup [in C:\Users\Sergey\Desktop\Brainfor\app\__init__.py:57]
2024-10-23 13:47:29,440 INFO: Microblog startup [in C:\Users\Sergey\Desktop\Brainfor\app\__init__.py:57]
2024-10-23 13:47:37,273 INFO: Microblog startup [in C:\Users\Sergey\Desktop\Brainfor\app\__init__.py:57]
2024-10-23 13:51:13,315 INFO: Microblog startup [in C:\Users\Sergey\Desktop\Brainfor\app\__init__.py:57]
2024-10-23 13:51:34,346 INFO: Microblog startup [in C:\Users\Sergey\Desktop\Brainfor\app\__init__.py:57]
2024-10-23 13:51:35,276 ERROR: Exception on /profile/ [GET] [in C:\Users\Sergey\AppData\Local\Programs\Python\Python311\Lib\site-packages\flask\app.py:838]
Traceback (most recent call last):
  File "C:\Users\Sergey\AppData\Local\Programs\Python\Python311\Lib\site-packages\flask\app.py", line 1473, in wsgi_app
    response = self.full_dispatch_request()
               ^^^^^^^^^^^^^^^^^^^^^^^^^^^^
  File "C:\Users\Sergey\AppData\Local\Programs\Python\Python311\Lib\site-packages\flask\app.py", line 882, in full_dispatch_request
    rv = self.handle_user_exception(e)
         ^^^^^^^^^^^^^^^^^^^^^^^^^^^^^
  File "C:\Users\Sergey\AppData\Local\Programs\Python\Python311\Lib\site-packages\flask\app.py", line 880, in full_dispatch_request
    rv = self.dispatch_request()
         ^^^^^^^^^^^^^^^^^^^^^^^
  File "C:\Users\Sergey\AppData\Local\Programs\Python\Python311\Lib\site-packages\flask\app.py", line 865, in dispatch_request
    return self.ensure_sync(self.view_functions[rule.endpoint])(**view_args)  # type: ignore[no-any-return]
           ^^^^^^^^^^^^^^^^^^^^^^^^^^^^^^^^^^^^^^^^^^^^^^^^^^^^^^^^^^^^^^^^^
  File "C:\Users\Sergey\AppData\Local\Programs\Python\Python311\Lib\site-packages\flask_login\utils.py", line 290, in decorated_view
    return current_app.ensure_sync(func)(*args, **kwargs)
           ^^^^^^^^^^^^^^^^^^^^^^^^^^^^^^^^^^^^^^^^^^^^^^
  File "C:\Users\Sergey\Desktop\Brainfor\app\main\routes.py", line 74, in information
    return render_template('main/information.html', info=info,  role=current_user.role, teachers=teachers,
           ^^^^^^^^^^^^^^^^^^^^^^^^^^^^^^^^^^^^^^^^^^^^^^^^^^^^^^^^^^^^^^^^^^^^^^^^^^^^^^^^^^^^^^^^^^^^^^^
  File "C:\Users\Sergey\AppData\Local\Programs\Python\Python311\Lib\site-packages\flask\templating.py", line 150, in render_template
    return _render(app, template, context)
           ^^^^^^^^^^^^^^^^^^^^^^^^^^^^^^^
  File "C:\Users\Sergey\AppData\Local\Programs\Python\Python311\Lib\site-packages\flask\templating.py", line 131, in _render
    rv = template.render(context)
         ^^^^^^^^^^^^^^^^^^^^^^^^
  File "C:\Users\Sergey\AppData\Local\Programs\Python\Python311\Lib\site-packages\jinja2\environment.py", line 1304, in render
    self.environment.handle_exception()
  File "C:\Users\Sergey\AppData\Local\Programs\Python\Python311\Lib\site-packages\jinja2\environment.py", line 939, in handle_exception
    raise rewrite_traceback_stack(source=source)
  File "C:\Users\Sergey\Desktop\Brainfor\app\templates\main\information.html", line 1, in top-level template code
    {% extends 'base.html' %}
  File "C:\Users\Sergey\Desktop\Brainfor\app\templates\base.html", line 52, in top-level template code
    {% block app_content %}
  File "C:\Users\Sergey\Desktop\Brainfor\app\templates\main\information.html", line 58, in block 'app_content'
    {{ teacher.name }}
  File "C:\Users\Sergey\AppData\Local\Programs\Python\Python311\Lib\site-packages\jinja2\environment.py", line 487, in getattr
    return getattr(obj, attribute)
           ^^^^^^^^^^^^^^^^^^^^^^^
jinja2.exceptions.UndefinedError: 'teacher' is undefined
2024-10-23 13:52:06,249 INFO: Microblog startup [in C:\Users\Sergey\Desktop\Brainfor\app\__init__.py:57]
2024-10-23 14:43:07,130 INFO: Microblog startup [in C:\Users\Sergey\Desktop\Brainfor\app\__init__.py:57]
2024-10-23 14:43:43,589 INFO: Microblog startup [in C:\Users\Sergey\Desktop\Brainfor\app\__init__.py:57]
