2024-10-16 10:57:33,868 ERROR: Exception on /add_graph_to/3 [GET] [in C:\Users\Sergey\AppData\Local\Programs\Python\Python311\Lib\site-packages\flask\app.py:838]
Traceback (most recent call last):
  File "C:\Users\Sergey\AppData\Local\Programs\Python\Python311\Lib\site-packages\flask\app.py", line 1473, in wsgi_app
    response = self.full_dispatch_request()
               ^^^^^^^^^^^^^^^^^^^^^^^^^^^^
  File "C:\Users\Sergey\AppData\Local\Programs\Python\Python311\Lib\site-packages\flask\app.py", line 882, in full_dispatch_request
    rv = self.handle_user_exception(e)
         ^^^^^^^^^^^^^^^^^^^^^^^^^^^^^
  File "C:\Users\Sergey\AppData\Local\Programs\Python\Python311\Lib\site-packages\flask\app.py", line 880, in full_dispatch_request
    rv = self.dispatch_request()
         ^^^^^^^^^^^^^^^^^^^^^^^
  File "C:\Users\Sergey\AppData\Local\Programs\Python\Python311\Lib\site-packages\flask\app.py", line 865, in dispatch_request
    return self.ensure_sync(self.view_functions[rule.endpoint])(**view_args)  # type: ignore[no-any-return]
           ^^^^^^^^^^^^^^^^^^^^^^^^^^^^^^^^^^^^^^^^^^^^^^^^^^^^^^^^^^^^^^^^^
  File "C:\Users\Sergey\Desktop\Brainfor\app\main\routes.py", line 213, in add_graficks
    form = GraphForm(id)
           ^^^^^^^^^^^^^
  File "C:\Users\Sergey\AppData\Local\Programs\Python\Python311\Lib\site-packages\wtforms\form.py", line 208, in __call__
    return type.__call__(cls, *args, **kwargs)
           ^^^^^^^^^^^^^^^^^^^^^^^^^^^^^^^^^^^
  File "C:\Users\Sergey\AppData\Local\Programs\Python\Python311\Lib\site-packages\flask_wtf\form.py", line 73, in __init__
    super().__init__(formdata=formdata, **kwargs)
  File "C:\Users\Sergey\AppData\Local\Programs\Python\Python311\Lib\site-packages\wtforms\form.py", line 286, in __init__
    self.process(formdata, obj, data=data, **kwargs)
  File "C:\Users\Sergey\AppData\Local\Programs\Python\Python311\Lib\site-packages\wtforms\form.py", line 127, in process
    field.process(formdata, data, extra_filters=field_extra_filters)
  File "C:\Users\Sergey\AppData\Local\Programs\Python\Python311\Lib\site-packages\wtforms\fields\core.py", line 326, in process
    if self.name in formdata:
       ^^^^^^^^^^^^^^^^^^^^^
TypeError: argument of type 'int' is not iterable
2024-10-16 10:57:43,349 INFO: Microblog startup [in C:\Users\Sergey\Desktop\Brainfor\app\__init__.py:57]
2024-10-16 10:57:46,901 ERROR: Exception on /add_graph_to/3 [GET] [in C:\Users\Sergey\AppData\Local\Programs\Python\Python311\Lib\site-packages\flask\app.py:838]
Traceback (most recent call last):
  File "C:\Users\Sergey\AppData\Local\Programs\Python\Python311\Lib\site-packages\flask\app.py", line 1473, in wsgi_app
    response = self.full_dispatch_request()
               ^^^^^^^^^^^^^^^^^^^^^^^^^^^^
  File "C:\Users\Sergey\AppData\Local\Programs\Python\Python311\Lib\site-packages\flask\app.py", line 882, in full_dispatch_request
    rv = self.handle_user_exception(e)
         ^^^^^^^^^^^^^^^^^^^^^^^^^^^^^
  File "C:\Users\Sergey\AppData\Local\Programs\Python\Python311\Lib\site-packages\flask\app.py", line 880, in full_dispatch_request
    rv = self.dispatch_request()
         ^^^^^^^^^^^^^^^^^^^^^^^
  File "C:\Users\Sergey\AppData\Local\Programs\Python\Python311\Lib\site-packages\flask\app.py", line 865, in dispatch_request
    return self.ensure_sync(self.view_functions[rule.endpoint])(**view_args)  # type: ignore[no-any-return]
           ^^^^^^^^^^^^^^^^^^^^^^^^^^^^^^^^^^^^^^^^^^^^^^^^^^^^^^^^^^^^^^^^^
  File "C:\Users\Sergey\Desktop\Brainfor\app\main\routes.py", line 213, in add_graficks
    form = GraphForm(id)
           ^^^^^^^^^^^^^
  File "C:\Users\Sergey\AppData\Local\Programs\Python\Python311\Lib\site-packages\wtforms\form.py", line 208, in __call__
    return type.__call__(cls, *args, **kwargs)
           ^^^^^^^^^^^^^^^^^^^^^^^^^^^^^^^^^^^
  File "C:\Users\Sergey\AppData\Local\Programs\Python\Python311\Lib\site-packages\flask_wtf\form.py", line 73, in __init__
    super().__init__(formdata=formdata, **kwargs)
  File "C:\Users\Sergey\AppData\Local\Programs\Python\Python311\Lib\site-packages\wtforms\form.py", line 286, in __init__
    self.process(formdata, obj, data=data, **kwargs)
  File "C:\Users\Sergey\AppData\Local\Programs\Python\Python311\Lib\site-packages\wtforms\form.py", line 127, in process
    field.process(formdata, data, extra_filters=field_extra_filters)
  File "C:\Users\Sergey\AppData\Local\Programs\Python\Python311\Lib\site-packages\wtforms\fields\core.py", line 326, in process
    if self.name in formdata:
       ^^^^^^^^^^^^^^^^^^^^^
TypeError: argument of type 'int' is not iterable
2024-10-16 10:57:51,687 ERROR: Exception on /add_graph_to/3 [GET] [in C:\Users\Sergey\AppData\Local\Programs\Python\Python311\Lib\site-packages\flask\app.py:838]
Traceback (most recent call last):
  File "C:\Users\Sergey\AppData\Local\Programs\Python\Python311\Lib\site-packages\flask\app.py", line 1473, in wsgi_app
    response = self.full_dispatch_request()
               ^^^^^^^^^^^^^^^^^^^^^^^^^^^^
  File "C:\Users\Sergey\AppData\Local\Programs\Python\Python311\Lib\site-packages\flask\app.py", line 882, in full_dispatch_request
    rv = self.handle_user_exception(e)
         ^^^^^^^^^^^^^^^^^^^^^^^^^^^^^
  File "C:\Users\Sergey\AppData\Local\Programs\Python\Python311\Lib\site-packages\flask\app.py", line 880, in full_dispatch_request
    rv = self.dispatch_request()
         ^^^^^^^^^^^^^^^^^^^^^^^
  File "C:\Users\Sergey\AppData\Local\Programs\Python\Python311\Lib\site-packages\flask\app.py", line 865, in dispatch_request
    return self.ensure_sync(self.view_functions[rule.endpoint])(**view_args)  # type: ignore[no-any-return]
           ^^^^^^^^^^^^^^^^^^^^^^^^^^^^^^^^^^^^^^^^^^^^^^^^^^^^^^^^^^^^^^^^^
  File "C:\Users\Sergey\Desktop\Brainfor\app\main\routes.py", line 213, in add_graficks
    form = GraphForm(id)
           ^^^^^^^^^^^^^
  File "C:\Users\Sergey\AppData\Local\Programs\Python\Python311\Lib\site-packages\wtforms\form.py", line 208, in __call__
    return type.__call__(cls, *args, **kwargs)
           ^^^^^^^^^^^^^^^^^^^^^^^^^^^^^^^^^^^
  File "C:\Users\Sergey\AppData\Local\Programs\Python\Python311\Lib\site-packages\flask_wtf\form.py", line 73, in __init__
    super().__init__(formdata=formdata, **kwargs)
  File "C:\Users\Sergey\AppData\Local\Programs\Python\Python311\Lib\site-packages\wtforms\form.py", line 286, in __init__
    self.process(formdata, obj, data=data, **kwargs)
  File "C:\Users\Sergey\AppData\Local\Programs\Python\Python311\Lib\site-packages\wtforms\form.py", line 127, in process
    field.process(formdata, data, extra_filters=field_extra_filters)
  File "C:\Users\Sergey\AppData\Local\Programs\Python\Python311\Lib\site-packages\wtforms\fields\core.py", line 326, in process
    if self.name in formdata:
       ^^^^^^^^^^^^^^^^^^^^^
TypeError: argument of type 'int' is not iterable
2024-10-16 10:58:23,481 INFO: Microblog startup [in C:\Users\Sergey\Desktop\Brainfor\app\__init__.py:57]
2024-10-16 12:47:37,333 INFO: Microblog startup [in C:\Users\Sergey\Desktop\Brainfor\app\__init__.py:57]
2024-10-16 12:47:54,199 INFO: Microblog startup [in C:\Users\Sergey\Desktop\Brainfor\app\__init__.py:57]
2024-10-16 12:49:04,390 INFO: Microblog startup [in C:\Users\Sergey\Desktop\Brainfor\app\__init__.py:57]
2024-10-16 12:49:53,785 INFO: Microblog startup [in C:\Users\Sergey\Desktop\Brainfor\app\__init__.py:57]
2024-10-16 12:51:29,574 INFO: Microblog startup [in C:\Users\Sergey\Desktop\Brainfor\app\__init__.py:57]
2024-10-16 12:53:09,465 INFO: Microblog startup [in C:\Users\Sergey\Desktop\Brainfor\app\__init__.py:57]
2024-10-16 12:53:36,659 INFO: Microblog startup [in C:\Users\Sergey\Desktop\Brainfor\app\__init__.py:57]
