2024-10-23 15:27:58,641 ERROR: Exception on /tempfix [GET] [in C:\Users\Sergey\AppData\Local\Programs\Python\Python311\Lib\site-packages\flask\app.py:838]
Traceback (most recent call last):
  File "C:\Users\Sergey\AppData\Local\Programs\Python\Python311\Lib\site-packages\flask\app.py", line 1473, in wsgi_app
    response = self.full_dispatch_request()
               ^^^^^^^^^^^^^^^^^^^^^^^^^^^^
  File "C:\Users\Sergey\AppData\Local\Programs\Python\Python311\Lib\site-packages\flask\app.py", line 882, in full_dispatch_request
    rv = self.handle_user_exception(e)
         ^^^^^^^^^^^^^^^^^^^^^^^^^^^^^
  File "C:\Users\Sergey\AppData\Local\Programs\Python\Python311\Lib\site-packages\flask\app.py", line 880, in full_dispatch_request
    rv = self.dispatch_request()
         ^^^^^^^^^^^^^^^^^^^^^^^
  File "C:\Users\Sergey\AppData\Local\Programs\Python\Python311\Lib\site-packages\flask\app.py", line 865, in dispatch_request
    return self.ensure_sync(self.view_functions[rule.endpoint])(**view_args)  # type: ignore[no-any-return]
           ^^^^^^^^^^^^^^^^^^^^^^^^^^^^^^^^^^^^^^^^^^^^^^^^^^^^^^^^^^^^^^^^^
  File "C:\Users\Sergey\AppData\Local\Programs\Python\Python311\Lib\site-packages\flask_login\utils.py", line 290, in decorated_view
    return current_app.ensure_sync(func)(*args, **kwargs)
           ^^^^^^^^^^^^^^^^^^^^^^^^^^^^^^^^^^^^^^^^^^^^^^
  File "C:\Users\Sergey\Desktop\Brainfor\app\main\routes.py", line 458, in tempfix
    i.Graficks.id_Teacher = key[i.Graficks.id_Student]
                                ^^^^^^^^^^^^^^^^^^^^^
AttributeError: 'Graficks' object has no attribute 'id_Student'
2024-10-23 15:28:33,181 INFO: Microblog startup [in C:\Users\Sergey\Desktop\Brainfor\app\__init__.py:57]
2024-10-23 15:28:35,080 ERROR: Exception on /tempfix [GET] [in C:\Users\Sergey\AppData\Local\Programs\Python\Python311\Lib\site-packages\flask\app.py:838]
Traceback (most recent call last):
  File "C:\Users\Sergey\AppData\Local\Programs\Python\Python311\Lib\site-packages\sqlalchemy\orm\session.py", line 3473, in add
    state = attributes.instance_state(instance)
            ^^^^^^^^^^^^^^^^^^^^^^^^^^^^^^^^^^^
AttributeError: 'list' object has no attribute '_sa_instance_state'

The above exception was the direct cause of the following exception:

Traceback (most recent call last):
  File "C:\Users\Sergey\AppData\Local\Programs\Python\Python311\Lib\site-packages\flask\app.py", line 1473, in wsgi_app
    response = self.full_dispatch_request()
               ^^^^^^^^^^^^^^^^^^^^^^^^^^^^
  File "C:\Users\Sergey\AppData\Local\Programs\Python\Python311\Lib\site-packages\flask\app.py", line 882, in full_dispatch_request
    rv = self.handle_user_exception(e)
         ^^^^^^^^^^^^^^^^^^^^^^^^^^^^^
  File "C:\Users\Sergey\AppData\Local\Programs\Python\Python311\Lib\site-packages\flask\app.py", line 880, in full_dispatch_request
    rv = self.dispatch_request()
         ^^^^^^^^^^^^^^^^^^^^^^^
  File "C:\Users\Sergey\AppData\Local\Programs\Python\Python311\Lib\site-packages\flask\app.py", line 865, in dispatch_request
    return self.ensure_sync(self.view_functions[rule.endpoint])(**view_args)  # type: ignore[no-any-return]
           ^^^^^^^^^^^^^^^^^^^^^^^^^^^^^^^^^^^^^^^^^^^^^^^^^^^^^^^^^^^^^^^^^
  File "C:\Users\Sergey\AppData\Local\Programs\Python\Python311\Lib\site-packages\flask_login\utils.py", line 290, in decorated_view
    return current_app.ensure_sync(func)(*args, **kwargs)
           ^^^^^^^^^^^^^^^^^^^^^^^^^^^^^^^^^^^^^^^^^^^^^^
  File "C:\Users\Sergey\Desktop\Brainfor\app\main\routes.py", line 461, in tempfix
    db.session.add(fixed)
  File "C:\Users\Sergey\AppData\Local\Programs\Python\Python311\Lib\site-packages\sqlalchemy\orm\scoping.py", line 378, in add
    return self._proxied.add(instance, _warn=_warn)
           ^^^^^^^^^^^^^^^^^^^^^^^^^^^^^^^^^^^^^^^^
  File "C:\Users\Sergey\AppData\Local\Programs\Python\Python311\Lib\site-packages\sqlalchemy\orm\session.py", line 3475, in add
    raise exc.UnmappedInstanceError(instance) from err
sqlalchemy.orm.exc.UnmappedInstanceError: Class 'builtins.list' is not mapped
2024-10-23 15:28:57,873 INFO: Microblog startup [in C:\Users\Sergey\Desktop\Brainfor\app\__init__.py:57]
2024-10-23 15:29:21,998 INFO: Microblog startup [in C:\Users\Sergey\Desktop\Brainfor\app\__init__.py:57]
2024-10-23 15:29:40,856 INFO: Microblog startup [in C:\Users\Sergey\Desktop\Brainfor\app\__init__.py:57]
2024-10-23 15:29:44,589 ERROR: Exception on /tempfix [GET] [in C:\Users\Sergey\AppData\Local\Programs\Python\Python311\Lib\site-packages\flask\app.py:838]
Traceback (most recent call last):
  File "C:\Users\Sergey\AppData\Local\Programs\Python\Python311\Lib\site-packages\sqlalchemy\orm\session.py", line 3473, in add
    state = attributes.instance_state(instance)
            ^^^^^^^^^^^^^^^^^^^^^^^^^^^^^^^^^^^
AttributeError: 'list' object has no attribute '_sa_instance_state'

The above exception was the direct cause of the following exception:

Traceback (most recent call last):
  File "C:\Users\Sergey\AppData\Local\Programs\Python\Python311\Lib\site-packages\flask\app.py", line 1473, in wsgi_app
    response = self.full_dispatch_request()
               ^^^^^^^^^^^^^^^^^^^^^^^^^^^^
  File "C:\Users\Sergey\AppData\Local\Programs\Python\Python311\Lib\site-packages\flask\app.py", line 882, in full_dispatch_request
    rv = self.handle_user_exception(e)
         ^^^^^^^^^^^^^^^^^^^^^^^^^^^^^
  File "C:\Users\Sergey\AppData\Local\Programs\Python\Python311\Lib\site-packages\flask\app.py", line 880, in full_dispatch_request
    rv = self.dispatch_request()
         ^^^^^^^^^^^^^^^^^^^^^^^
  File "C:\Users\Sergey\AppData\Local\Programs\Python\Python311\Lib\site-packages\flask\app.py", line 865, in dispatch_request
    return self.ensure_sync(self.view_functions[rule.endpoint])(**view_args)  # type: ignore[no-any-return]
           ^^^^^^^^^^^^^^^^^^^^^^^^^^^^^^^^^^^^^^^^^^^^^^^^^^^^^^^^^^^^^^^^^
  File "C:\Users\Sergey\AppData\Local\Programs\Python\Python311\Lib\site-packages\flask_login\utils.py", line 290, in decorated_view
    return current_app.ensure_sync(func)(*args, **kwargs)
           ^^^^^^^^^^^^^^^^^^^^^^^^^^^^^^^^^^^^^^^^^^^^^^
  File "C:\Users\Sergey\Desktop\Brainfor\app\main\routes.py", line 462, in tempfix
    db.session.add(fixed)
  File "C:\Users\Sergey\AppData\Local\Programs\Python\Python311\Lib\site-packages\sqlalchemy\orm\scoping.py", line 378, in add
    return self._proxied.add(instance, _warn=_warn)
           ^^^^^^^^^^^^^^^^^^^^^^^^^^^^^^^^^^^^^^^^
  File "C:\Users\Sergey\AppData\Local\Programs\Python\Python311\Lib\site-packages\sqlalchemy\orm\session.py", line 3475, in add
    raise exc.UnmappedInstanceError(instance) from err
sqlalchemy.orm.exc.UnmappedInstanceError: Class 'builtins.list' is not mapped
2024-10-23 15:29:51,907 INFO: Microblog startup [in C:\Users\Sergey\Desktop\Brainfor\app\__init__.py:57]
2024-10-23 15:47:02,982 INFO: Microblog startup [in C:\Users\Sergey\Desktop\Brainfor\app\__init__.py:57]
2024-10-24 12:11:38,618 INFO: Microblog startup [in C:\Users\Sergey\Desktop\Brainfor\app\__init__.py:57]
