2024-10-23 12:59:07,291 INFO: Microblog startup [in C:\Users\Sergey\Desktop\Brainfor\app\__init__.py:57]
2024-10-23 12:59:08,275 ERROR: Exception on /sudo_graph [GET] [in C:\Users\Sergey\AppData\Local\Programs\Python\Python311\Lib\site-packages\flask\app.py:838]
Traceback (most recent call last):
  File "C:\Users\Sergey\AppData\Local\Programs\Python\Python311\Lib\site-packages\flask\app.py", line 1473, in wsgi_app
    response = self.full_dispatch_request()
               ^^^^^^^^^^^^^^^^^^^^^^^^^^^^
  File "C:\Users\Sergey\AppData\Local\Programs\Python\Python311\Lib\site-packages\flask\app.py", line 882, in full_dispatch_request
    rv = self.handle_user_exception(e)
         ^^^^^^^^^^^^^^^^^^^^^^^^^^^^^
  File "C:\Users\Sergey\AppData\Local\Programs\Python\Python311\Lib\site-packages\flask\app.py", line 880, in full_dispatch_request
    rv = self.dispatch_request()
         ^^^^^^^^^^^^^^^^^^^^^^^
  File "C:\Users\Sergey\AppData\Local\Programs\Python\Python311\Lib\site-packages\flask\app.py", line 865, in dispatch_request
    return self.ensure_sync(self.view_functions[rule.endpoint])(**view_args)  # type: ignore[no-any-return]
           ^^^^^^^^^^^^^^^^^^^^^^^^^^^^^^^^^^^^^^^^^^^^^^^^^^^^^^^^^^^^^^^^^
  File "C:\Users\Sergey\AppData\Local\Programs\Python\Python311\Lib\site-packages\flask_login\utils.py", line 290, in decorated_view
    return current_app.ensure_sync(func)(*args, **kwargs)
           ^^^^^^^^^^^^^^^^^^^^^^^^^^^^^^^^^^^^^^^^^^^^^^
  File "C:\Users\Sergey\Desktop\Brainfor\app\main\admin_panel\admin_routes.py", line 174, in sudo_graph
    q = db.session.query(User).filtet(User.role > 1).all()
        ^^^^^^^^^^^^^^^^^^^^^^^^^^^^^
AttributeError: 'Query' object has no attribute 'filtet'
2024-10-23 12:59:27,745 INFO: Microblog startup [in C:\Users\Sergey\Desktop\Brainfor\app\__init__.py:57]
2024-10-23 13:00:40,380 INFO: Microblog startup [in C:\Users\Sergey\Desktop\Brainfor\app\__init__.py:57]
2024-10-23 13:00:41,361 ERROR: Exception on /sudo_graph [GET] [in C:\Users\Sergey\AppData\Local\Programs\Python\Python311\Lib\site-packages\flask\app.py:838]
Traceback (most recent call last):
  File "C:\Users\Sergey\AppData\Local\Programs\Python\Python311\Lib\site-packages\flask\app.py", line 1473, in wsgi_app
    response = self.full_dispatch_request()
               ^^^^^^^^^^^^^^^^^^^^^^^^^^^^
  File "C:\Users\Sergey\AppData\Local\Programs\Python\Python311\Lib\site-packages\flask\app.py", line 882, in full_dispatch_request
    rv = self.handle_user_exception(e)
         ^^^^^^^^^^^^^^^^^^^^^^^^^^^^^
  File "C:\Users\Sergey\AppData\Local\Programs\Python\Python311\Lib\site-packages\flask\app.py", line 880, in full_dispatch_request
    rv = self.dispatch_request()
         ^^^^^^^^^^^^^^^^^^^^^^^
  File "C:\Users\Sergey\AppData\Local\Programs\Python\Python311\Lib\site-packages\flask\app.py", line 865, in dispatch_request
    return self.ensure_sync(self.view_functions[rule.endpoint])(**view_args)  # type: ignore[no-any-return]
           ^^^^^^^^^^^^^^^^^^^^^^^^^^^^^^^^^^^^^^^^^^^^^^^^^^^^^^^^^^^^^^^^^
  File "C:\Users\Sergey\AppData\Local\Programs\Python\Python311\Lib\site-packages\flask_login\utils.py", line 290, in decorated_view
    return current_app.ensure_sync(func)(*args, **kwargs)
           ^^^^^^^^^^^^^^^^^^^^^^^^^^^^^^^^^^^^^^^^^^^^^^
  File "C:\Users\Sergey\Desktop\Brainfor\app\main\admin_panel\admin_routes.py", line 177, in sudo_graph
    teacher_key = {temp_inf.id_user : temp
                  ^^^^^^^^^^^^^^^^^^^^^^^^
  File "C:\Users\Sergey\Desktop\Brainfor\app\main\admin_panel\admin_routes.py", line 177, in <dictcomp>
    teacher_key = {temp_inf.id_user : temp
                   ^^^^^^^^
NameError: name 'temp_inf' is not defined
2024-10-23 13:01:00,399 INFO: Microblog startup [in C:\Users\Sergey\Desktop\Brainfor\app\__init__.py:57]
2024-10-23 13:05:11,009 INFO: Microblog startup [in C:\Users\Sergey\Desktop\Brainfor\app\__init__.py:57]
2024-10-23 13:07:07,953 INFO: Microblog startup [in C:\Users\Sergey\Desktop\Brainfor\app\__init__.py:57]
2024-10-23 13:08:27,938 INFO: Microblog startup [in C:\Users\Sergey\Desktop\Brainfor\app\__init__.py:57]
2024-10-23 13:08:30,106 ERROR: Exception on /sudo_graph [GET] [in C:\Users\Sergey\AppData\Local\Programs\Python\Python311\Lib\site-packages\flask\app.py:838]
Traceback (most recent call last):
  File "C:\Users\Sergey\AppData\Local\Programs\Python\Python311\Lib\site-packages\flask\app.py", line 1473, in wsgi_app
    response = self.full_dispatch_request()
               ^^^^^^^^^^^^^^^^^^^^^^^^^^^^
  File "C:\Users\Sergey\AppData\Local\Programs\Python\Python311\Lib\site-packages\flask\app.py", line 882, in full_dispatch_request
    rv = self.handle_user_exception(e)
         ^^^^^^^^^^^^^^^^^^^^^^^^^^^^^
  File "C:\Users\Sergey\AppData\Local\Programs\Python\Python311\Lib\site-packages\flask\app.py", line 880, in full_dispatch_request
    rv = self.dispatch_request()
         ^^^^^^^^^^^^^^^^^^^^^^^
  File "C:\Users\Sergey\AppData\Local\Programs\Python\Python311\Lib\site-packages\flask\app.py", line 865, in dispatch_request
    return self.ensure_sync(self.view_functions[rule.endpoint])(**view_args)  # type: ignore[no-any-return]
           ^^^^^^^^^^^^^^^^^^^^^^^^^^^^^^^^^^^^^^^^^^^^^^^^^^^^^^^^^^^^^^^^^
  File "C:\Users\Sergey\AppData\Local\Programs\Python\Python311\Lib\site-packages\flask_login\utils.py", line 290, in decorated_view
    return current_app.ensure_sync(func)(*args, **kwargs)
           ^^^^^^^^^^^^^^^^^^^^^^^^^^^^^^^^^^^^^^^^^^^^^^
  File "C:\Users\Sergey\Desktop\Brainfor\app\main\admin_panel\admin_routes.py", line 193, in sudo_graph
    return render_template('admin_panel/sudo_graph.html', graph=graph, rolee=role, teacher_key=teacher_key,
           ^^^^^^^^^^^^^^^^^^^^^^^^^^^^^^^^^^^^^^^^^^^^^^^^^^^^^^^^^^^^^^^^^^^^^^^^^^^^^^^^^^^^^^^^^^^^^^^^
  File "C:\Users\Sergey\AppData\Local\Programs\Python\Python311\Lib\site-packages\flask\templating.py", line 150, in render_template
    return _render(app, template, context)
           ^^^^^^^^^^^^^^^^^^^^^^^^^^^^^^^
  File "C:\Users\Sergey\AppData\Local\Programs\Python\Python311\Lib\site-packages\flask\templating.py", line 131, in _render
    rv = template.render(context)
         ^^^^^^^^^^^^^^^^^^^^^^^^
  File "C:\Users\Sergey\AppData\Local\Programs\Python\Python311\Lib\site-packages\jinja2\environment.py", line 1304, in render
    self.environment.handle_exception()
  File "C:\Users\Sergey\AppData\Local\Programs\Python\Python311\Lib\site-packages\jinja2\environment.py", line 939, in handle_exception
    raise rewrite_traceback_stack(source=source)
  File "C:\Users\Sergey\Desktop\Brainfor\app\templates\admin_panel\sudo_graph.html", line 1, in top-level template code
    {% extends 'base.html' %}
  File "C:\Users\Sergey\Desktop\Brainfor\app\templates\base.html", line 52, in top-level template code
    {% block app_content %}
  File "C:\Users\Sergey\Desktop\Brainfor\app\templates\admin_panel\sudo_graph.html", line 64, in block 'app_content'
    {{ teacher_key[graph[i].id_Teacher.name] }}
    ^^^^^^^^^^^^^^^^^^^^^^^^^
  File "C:\Users\Sergey\AppData\Local\Programs\Python\Python311\Lib\site-packages\jinja2\environment.py", line 487, in getattr
    return getattr(obj, attribute)
           ^^^^^^^^^^^^^^^^^^^^^^^
jinja2.exceptions.UndefinedError: 'sqlalchemy.engine.row.Row object' has no attribute 'id_Teacher'
2024-10-23 13:08:52,126 INFO: Microblog startup [in C:\Users\Sergey\Desktop\Brainfor\app\__init__.py:57]
