2024-01-25 16:47:07,596 ERROR: Exception on / [GET] [in c:\users\abifa\desktop\brainfor\venv\lib\site-packages\flask\app.py:825]
Traceback (most recent call last):
  File "c:\users\abifa\desktop\brainfor\venv\lib\site-packages\sqlalchemy\orm\clsregistry.py", line 515, in _resolve_name
    rval = d[token]
  File "c:\users\abifa\desktop\brainfor\venv\lib\site-packages\sqlalchemy\util\_collections.py", line 346, in __missing__
    self[key] = val = self.creator(key)
  File "c:\users\abifa\desktop\brainfor\venv\lib\site-packages\sqlalchemy\orm\clsregistry.py", line 483, in _access_cls
    return self.fallback[key]
KeyError: 'Lesson'

The above exception was the direct cause of the following exception:

Traceback (most recent call last):
  File "c:\users\abifa\desktop\brainfor\venv\lib\site-packages\flask\app.py", line 1455, in wsgi_app
    response = self.full_dispatch_request()
  File "c:\users\abifa\desktop\brainfor\venv\lib\site-packages\flask\app.py", line 869, in full_dispatch_request
    rv = self.handle_user_exception(e)
  File "c:\users\abifa\desktop\brainfor\venv\lib\site-packages\flask\app.py", line 867, in full_dispatch_request
    rv = self.dispatch_request()
  File "c:\users\abifa\desktop\brainfor\venv\lib\site-packages\flask\app.py", line 852, in dispatch_request
    return self.ensure_sync(self.view_functions[rule.endpoint])(**view_args)
  File "c:\users\abifa\desktop\brainfor\venv\lib\site-packages\flask_login\utils.py", line 284, in decorated_view
    elif not current_user.is_authenticated:
  File "c:\users\abifa\desktop\brainfor\venv\lib\site-packages\werkzeug\local.py", line 316, in __get__
    obj = instance._get_current_object()  # type: ignore[misc]
  File "c:\users\abifa\desktop\brainfor\venv\lib\site-packages\werkzeug\local.py", line 520, in _get_current_object
    return get_name(local())  # type: ignore
  File "c:\users\abifa\desktop\brainfor\venv\lib\site-packages\flask_login\utils.py", line 25, in <lambda>
    current_user = LocalProxy(lambda: _get_user())
  File "c:\users\abifa\desktop\brainfor\venv\lib\site-packages\flask_login\utils.py", line 372, in _get_user
    current_app.login_manager._load_user()
  File "c:\users\abifa\desktop\brainfor\venv\lib\site-packages\flask_login\login_manager.py", line 364, in _load_user
    user = self._user_callback(user_id)
  File "C:\Users\abifa\Desktop\Brainfor\app\models\user.py", line 11, in load_user
    return User.query.get(int(id))
  File "c:\users\abifa\desktop\brainfor\venv\lib\site-packages\flask_sqlalchemy\model.py", line 22, in __get__
    return cls.query_class(
  File "c:\users\abifa\desktop\brainfor\venv\lib\site-packages\sqlalchemy\orm\query.py", line 276, in __init__
    self._set_entities(entities)
  File "c:\users\abifa\desktop\brainfor\venv\lib\site-packages\sqlalchemy\orm\query.py", line 288, in _set_entities
    self._raw_columns = [
  File "c:\users\abifa\desktop\brainfor\venv\lib\site-packages\sqlalchemy\orm\query.py", line 289, in <listcomp>
    coercions.expect(
  File "c:\users\abifa\desktop\brainfor\venv\lib\site-packages\sqlalchemy\sql\coercions.py", line 406, in expect
    insp._post_inspect
  File "c:\users\abifa\desktop\brainfor\venv\lib\site-packages\sqlalchemy\util\langhelpers.py", line 1253, in __get__
    obj.__dict__[self.__name__] = result = self.fget(obj)
  File "c:\users\abifa\desktop\brainfor\venv\lib\site-packages\sqlalchemy\orm\mapper.py", line 2707, in _post_inspect
    self._check_configure()
  File "c:\users\abifa\desktop\brainfor\venv\lib\site-packages\sqlalchemy\orm\mapper.py", line 2386, in _check_configure
    _configure_registries({self.registry}, cascade=True)
  File "c:\users\abifa\desktop\brainfor\venv\lib\site-packages\sqlalchemy\orm\mapper.py", line 4199, in _configure_registries
    _do_configure_registries(registries, cascade)
  File "c:\users\abifa\desktop\brainfor\venv\lib\site-packages\sqlalchemy\orm\mapper.py", line 4240, in _do_configure_registries
    mapper._post_configure_properties()
  File "c:\users\abifa\desktop\brainfor\venv\lib\site-packages\sqlalchemy\orm\mapper.py", line 2403, in _post_configure_properties
    prop.init()
  File "c:\users\abifa\desktop\brainfor\venv\lib\site-packages\sqlalchemy\orm\interfaces.py", line 579, in init
    self.do_init()
  File "c:\users\abifa\desktop\brainfor\venv\lib\site-packages\sqlalchemy\orm\relationships.py", line 1635, in do_init
    self._setup_entity()
  File "c:\users\abifa\desktop\brainfor\venv\lib\site-packages\sqlalchemy\orm\relationships.py", line 1852, in _setup_entity
    self._clsregistry_resolve_name(argument)(),
  File "c:\users\abifa\desktop\brainfor\venv\lib\site-packages\sqlalchemy\orm\clsregistry.py", line 519, in _resolve_name
    self._raise_for_name(name, err)
  File "c:\users\abifa\desktop\brainfor\venv\lib\site-packages\sqlalchemy\orm\clsregistry.py", line 500, in _raise_for_name
    raise exc.InvalidRequestError(
sqlalchemy.exc.InvalidRequestError: When initializing mapper Mapper[User(user)], expression 'Lesson' failed to locate a name ('Lesson'). If this is a class name, consider adding this relationship() to the <class 'app.models.user.User'> class after both dependent classes have been defined.
2024-01-25 16:50:27,955 INFO: Microblog startup [in C:\Users\abifa\Desktop\Brainfor\app\__init__.py:57]
2024-01-25 16:50:35,047 INFO: Microblog startup [in C:\Users\abifa\Desktop\Brainfor\app\__init__.py:57]
2024-01-25 16:50:50,077 INFO: Microblog startup [in C:\Users\abifa\Desktop\Brainfor\app\__init__.py:57]
2024-01-26 05:40:44,638 INFO: Microblog startup [in C:\Users\abifa\Desktop\Brainfor\app\__init__.py:57]
2024-01-26 05:40:52,899 INFO: Microblog startup [in C:\Users\abifa\Desktop\Brainfor\app\__init__.py:57]
2024-01-26 05:42:17,388 INFO: Microblog startup [in C:\Users\abifa\Desktop\Brainfor\app\__init__.py:57]
2024-01-26 05:42:25,598 INFO: Microblog startup [in C:\Users\abifa\Desktop\Brainfor\app\__init__.py:57]
2024-01-26 05:42:31,708 INFO: Microblog startup [in C:\Users\abifa\Desktop\Brainfor\app\__init__.py:57]
2024-01-26 05:42:53,338 INFO: Microblog startup [in C:\Users\abifa\Desktop\Brainfor\app\__init__.py:57]
2024-01-26 05:46:42,248 INFO: Microblog startup [in C:\Users\abifa\Desktop\Brainfor\app\__init__.py:57]
2024-01-26 05:46:52,958 INFO: Microblog startup [in C:\Users\abifa\Desktop\Brainfor\app\__init__.py:57]
2024-01-26 05:47:06,138 INFO: Microblog startup [in C:\Users\abifa\Desktop\Brainfor\app\__init__.py:57]
2024-01-26 05:48:32,358 INFO: Microblog startup [in C:\Users\abifa\Desktop\Brainfor\app\__init__.py:57]
2024-01-26 05:53:24,392 INFO: Microblog startup [in C:\Users\abifa\Desktop\Brainfor\app\__init__.py:57]
2024-01-26 05:53:27,072 ERROR: Exception on / [GET] [in c:\users\abifa\desktop\brainfor\venv\lib\site-packages\flask\app.py:825]
Traceback (most recent call last):
  File "c:\users\abifa\desktop\brainfor\venv\lib\site-packages\flask\app.py", line 1455, in wsgi_app
    response = self.full_dispatch_request()
  File "c:\users\abifa\desktop\brainfor\venv\lib\site-packages\flask\app.py", line 869, in full_dispatch_request
    rv = self.handle_user_exception(e)
  File "c:\users\abifa\desktop\brainfor\venv\lib\site-packages\flask\app.py", line 867, in full_dispatch_request
    rv = self.dispatch_request()
  File "c:\users\abifa\desktop\brainfor\venv\lib\site-packages\flask\app.py", line 852, in dispatch_request
    return self.ensure_sync(self.view_functions[rule.endpoint])(**view_args)
  File "c:\users\abifa\desktop\brainfor\venv\lib\site-packages\flask_login\utils.py", line 290, in decorated_view
    return current_app.ensure_sync(func)(*args, **kwargs)
  File "C:\Users\abifa\Desktop\Brainfor\app\main\routes.py", line 15, in index
    return render_template('index.html')
  File "c:\users\abifa\desktop\brainfor\venv\lib\site-packages\flask\templating.py", line 152, in render_template
    return _render(app, template, context)
  File "c:\users\abifa\desktop\brainfor\venv\lib\site-packages\flask\templating.py", line 133, in _render
    rv = template.render(context)
  File "c:\users\abifa\desktop\brainfor\venv\lib\site-packages\jinja2\environment.py", line 1301, in render
    self.environment.handle_exception()
  File "c:\users\abifa\desktop\brainfor\venv\lib\site-packages\jinja2\environment.py", line 936, in handle_exception
    raise rewrite_traceback_stack(source=source)
  File "C:\Users\abifa\Desktop\Brainfor\app\templates\index.html", line 1, in top-level template code
    {% extends 'base.html' %}
  File "c:\users\abifa\desktop\brainfor\venv\lib\site-packages\jinja2\environment.py", line 936, in handle_exception
    raise rewrite_traceback_stack(source=source)
  File "C:\Users\abifa\Desktop\Brainfor\app\templates\base.html", line 27, in template
    {% if current_user.role=2 %}
jinja2.exceptions.TemplateSyntaxError: expected token 'end of statement block', got '='
2024-01-26 05:53:44,292 INFO: Microblog startup [in C:\Users\abifa\Desktop\Brainfor\app\__init__.py:57]
